<?xml version="1.0" encoding="UTF-8"?>
<testng-results skipped="0" failed="2" total="3" passed="1">
  <reporter-output>
  </reporter-output>
  <suite name="Default suite" duration-ms="82" started-at="2021-10-30T12:33:32Z" finished-at="2021-10-30T12:33:32Z">
    <groups>
    </groups>
    <test name="Default test" duration-ms="82" started-at="2021-10-30T12:33:32Z" finished-at="2021-10-30T12:33:32Z">
      <class name="frameworke_implementation.Assertion_testNG">
        <test-method status="FAIL" signature="testcase1()[pri:0, instance:frameworke_implementation.Assertion_testNG@72d818d1]" name="testcase1" duration-ms="26" started-at="2021-10-30T18:33:32Z" finished-at="2021-10-30T18:33:32Z">
          <exception class="java.lang.AssertionError">
            <message>
              <![CDATA[The following asserts failed:
	expected [false] but found [true],
	expected [2] but found [1],
	expected [false] but found [true]]]>
            </message>
            <full-stacktrace>
              <![CDATA[java.lang.AssertionError: The following asserts failed:
	expected [false] but found [true],
	expected [2] but found [1],
	expected [false] but found [true]
	at org.testng.asserts.SoftAssert.assertAll(SoftAssert.java:43)
	at frameworke_implementation.Assertion_testNG.testcase1(Assertion_testNG.java:41)
	at sun.reflect.NativeMethodAccessorImpl.invoke0(Native Method)
	at sun.reflect.NativeMethodAccessorImpl.invoke(Unknown Source)
	at sun.reflect.DelegatingMethodAccessorImpl.invoke(Unknown Source)
	at java.lang.reflect.Method.invoke(Unknown Source)
	at org.testng.internal.MethodInvocationHelper.invokeMethod(MethodInvocationHelper.java:100)
	at org.testng.internal.Invoker.invokeMethod(Invoker.java:646)
	at org.testng.internal.Invoker.invokeTestMethod(Invoker.java:811)
	at org.testng.internal.Invoker.invokeTestMethods(Invoker.java:1137)
	at org.testng.internal.TestMethodWorker.invokeTestMethods(TestMethodWorker.java:129)
	at org.testng.internal.TestMethodWorker.run(TestMethodWorker.java:112)
	at org.testng.TestRunner.privateRun(TestRunner.java:753)
	at org.testng.TestRunner.run(TestRunner.java:607)
	at org.testng.SuiteRunner.runTest(SuiteRunner.java:368)
	at org.testng.SuiteRunner.runSequentially(SuiteRunner.java:363)
	at org.testng.SuiteRunner.privateRun(SuiteRunner.java:321)
	at org.testng.SuiteRunner.run(SuiteRunner.java:270)
	at org.testng.SuiteRunnerWorker.runSuite(SuiteRunnerWorker.java:52)
	at org.testng.SuiteRunnerWorker.run(SuiteRunnerWorker.java:86)
	at org.testng.TestNG.runSuitesSequentially(TestNG.java:1284)
	at org.testng.TestNG.runSuitesLocally(TestNG.java:1209)
	at org.testng.TestNG.runSuites(TestNG.java:1124)
	at org.testng.TestNG.run(TestNG.java:1096)
	at org.testng.remote.AbstractRemoteTestNG.run(AbstractRemoteTestNG.java:132)
	at org.testng.remote.RemoteTestNG.initAndRun(RemoteTestNG.java:236)
	at org.testng.remote.RemoteTestNG.main(RemoteTestNG.java:81)
]]>
            </full-stacktrace>
          </exception> <!-- java.lang.AssertionError -->
          <reporter-output>
          </reporter-output>
        </test-method> <!-- testcase1 -->
        <test-method status="PASS" signature="testcase2()[pri:0, instance:frameworke_implementation.Assertion_testNG@72d818d1]" name="testcase2" duration-ms="2" started-at="2021-10-30T18:33:32Z" finished-at="2021-10-30T18:33:32Z">
          <reporter-output>
          </reporter-output>
        </test-method> <!-- testcase2 -->
        <test-method status="FAIL" signature="testcase3()[pri:0, instance:frameworke_implementation.Assertion_testNG@72d818d1]" name="testcase3" duration-ms="4" started-at="2021-10-30T18:33:32Z" finished-at="2021-10-30T18:33:32Z">
          <exception class="java.lang.AssertionError">
            <message>
              <![CDATA[The following asserts failed:
	expected [false] but found [true]]]>
            </message>
            <full-stacktrace>
              <![CDATA[java.lang.AssertionError: The following asserts failed:
	expected [false] but found [true]
	at org.testng.asserts.SoftAssert.assertAll(SoftAssert.java:43)
	at frameworke_implementation.Assertion_testNG.testcase3(Assertion_testNG.java:63)
	at sun.reflect.NativeMethodAccessorImpl.invoke0(Native Method)
	at sun.reflect.NativeMethodAccessorImpl.invoke(Unknown Source)
	at sun.reflect.DelegatingMethodAccessorImpl.invoke(Unknown Source)
	at java.lang.reflect.Method.invoke(Unknown Source)
	at org.testng.internal.MethodInvocationHelper.invokeMethod(MethodInvocationHelper.java:100)
	at org.testng.internal.Invoker.invokeMethod(Invoker.java:646)
	at org.testng.internal.Invoker.invokeTestMethod(Invoker.java:811)
	at org.testng.internal.Invoker.invokeTestMethods(Invoker.java:1137)
	at org.testng.internal.TestMethodWorker.invokeTestMethods(TestMethodWorker.java:129)
	at org.testng.internal.TestMethodWorker.run(TestMethodWorker.java:112)
	at org.testng.TestRunner.privateRun(TestRunner.java:753)
	at org.testng.TestRunner.run(TestRunner.java:607)
	at org.testng.SuiteRunner.runTest(SuiteRunner.java:368)
	at org.testng.SuiteRunner.runSequentially(SuiteRunner.java:363)
	at org.testng.SuiteRunner.privateRun(SuiteRunner.java:321)
	at org.testng.SuiteRunner.run(SuiteRunner.java:270)
	at org.testng.SuiteRunnerWorker.runSuite(SuiteRunnerWorker.java:52)
	at org.testng.SuiteRunnerWorker.run(SuiteRunnerWorker.java:86)
	at org.testng.TestNG.runSuitesSequentially(TestNG.java:1284)
	at org.testng.TestNG.runSuitesLocally(TestNG.java:1209)
	at org.testng.TestNG.runSuites(TestNG.java:1124)
	at org.testng.TestNG.run(TestNG.java:1096)
	at org.testng.remote.AbstractRemoteTestNG.run(AbstractRemoteTestNG.java:132)
	at org.testng.remote.RemoteTestNG.initAndRun(RemoteTestNG.java:236)
	at org.testng.remote.RemoteTestNG.main(RemoteTestNG.java:81)
]]>
            </full-stacktrace>
          </exception> <!-- java.lang.AssertionError -->
          <reporter-output>
          </reporter-output>
        </test-method> <!-- testcase3 -->
      </class> <!-- frameworke_implementation.Assertion_testNG -->
    </test> <!-- Default test -->
  </suite> <!-- Default suite -->
</testng-results>
